ERROR [2020-08-11 11:45:17] F:\dxr\Myproject\work\blueapps\core\exceptions\middleware.py 70 process_exception 6332 9232 
 	 捕获未处理异常,异常具体堆栈->[Traceback (most recent call last):
  File "D:\python\lib\site-packages\django\core\handlers\base.py", line 113, in _get_response
    response = wrapped_callback(request, *callback_args, **callback_kwargs)
  File "F:\dxr\Myproject\work\home_application\views.py", line 53, in say_hello
    return render_json(res)
  File "F:\dxr\Myproject\work\home_application\views.py", line 47, in render_json
    return HttpResponse(json_dumps(res_dict),content_type='application/json')
NameError: name 'json_dumps' is not defined
], 请求URL->[/sayhello/], 请求方法->[POST] 请求参数->[{"input": "11"}] 

ERROR [2020-08-11 11:45:22] F:\dxr\Myproject\work\blueapps\core\exceptions\middleware.py 70 process_exception 6332 9232 
 	 捕获未处理异常,异常具体堆栈->[Traceback (most recent call last):
  File "D:\python\lib\site-packages\django\core\handlers\base.py", line 113, in _get_response
    response = wrapped_callback(request, *callback_args, **callback_kwargs)
  File "F:\dxr\Myproject\work\home_application\views.py", line 53, in say_hello
    return render_json(res)
  File "F:\dxr\Myproject\work\home_application\views.py", line 47, in render_json
    return HttpResponse(json_dumps(res_dict),content_type='application/json')
NameError: name 'json_dumps' is not defined
], 请求URL->[/sayhello/], 请求方法->[POST] 请求参数->[{"input": "Hello"}] 

ERROR [2020-08-11 11:45:23] F:\dxr\Myproject\work\blueapps\core\exceptions\middleware.py 70 process_exception 6332 9232 
 	 捕获未处理异常,异常具体堆栈->[Traceback (most recent call last):
  File "D:\python\lib\site-packages\django\core\handlers\base.py", line 113, in _get_response
    response = wrapped_callback(request, *callback_args, **callback_kwargs)
  File "F:\dxr\Myproject\work\home_application\views.py", line 53, in say_hello
    return render_json(res)
  File "F:\dxr\Myproject\work\home_application\views.py", line 47, in render_json
    return HttpResponse(json_dumps(res_dict),content_type='application/json')
NameError: name 'json_dumps' is not defined
], 请求URL->[/sayhello/], 请求方法->[POST] 请求参数->[{"input": "Hello"}] 

ERROR [2020-08-11 11:45:23] F:\dxr\Myproject\work\blueapps\core\exceptions\middleware.py 70 process_exception 6332 9232 
 	 捕获未处理异常,异常具体堆栈->[Traceback (most recent call last):
  File "D:\python\lib\site-packages\django\core\handlers\base.py", line 113, in _get_response
    response = wrapped_callback(request, *callback_args, **callback_kwargs)
  File "F:\dxr\Myproject\work\home_application\views.py", line 53, in say_hello
    return render_json(res)
  File "F:\dxr\Myproject\work\home_application\views.py", line 47, in render_json
    return HttpResponse(json_dumps(res_dict),content_type='application/json')
NameError: name 'json_dumps' is not defined
], 请求URL->[/sayhello/], 请求方法->[POST] 请求参数->[{"input": "Hello"}] 

ERROR [2020-08-11 11:47:03] F:\dxr\Myproject\work\blueapps\core\exceptions\middleware.py 70 process_exception 2896 13620 
 	 捕获未处理异常,异常具体堆栈->[Traceback (most recent call last):
  File "D:\python\lib\site-packages\django\core\handlers\base.py", line 113, in _get_response
    response = wrapped_callback(request, *callback_args, **callback_kwargs)
  File "F:\dxr\Myproject\work\home_application\views.py", line 53, in say_hello
    return render_json(res)
  File "F:\dxr\Myproject\work\home_application\views.py", line 47, in render_json
    return HttpResponse(json_dumps(res_dict),content_type='application/json')
NameError: name 'json_dumps' is not defined
], 请求URL->[/sayhello/], 请求方法->[POST] 请求参数->[{"input": "Hello"}] 

ERROR [2020-08-11 11:48:49] F:\dxr\Myproject\work\blueapps\core\exceptions\middleware.py 70 process_exception 18068 4036 
 	 捕获未处理异常,异常具体堆栈->[Traceback (most recent call last):
  File "D:\python\lib\site-packages\django\core\handlers\base.py", line 113, in _get_response
    response = wrapped_callback(request, *callback_args, **callback_kwargs)
  File "F:\dxr\Myproject\work\home_application\views.py", line 53, in say_hello
    return render_json(res)
  File "F:\dxr\Myproject\work\home_application\views.py", line 47, in render_json
    return HttpResponse(json_dumps(res_dict),content_type='application/json')
NameError: name 'HttpResponse' is not defined
], 请求URL->[/sayhello/], 请求方法->[POST] 请求参数->[{"input": "Hello"}] 

ERROR [2020-08-11 11:59:56] F:\dxr\Myproject\work\blueapps\core\exceptions\middleware.py 70 process_exception 18208 4488 
 	 捕获未处理异常,异常具体堆栈->[Traceback (most recent call last):
  File "D:\python\lib\site-packages\django\core\handlers\base.py", line 113, in _get_response
    response = wrapped_callback(request, *callback_args, **callback_kwargs)
  File "F:\dxr\Myproject\work\home_application\views.py", line 49, in say_hello
    return render_json(res)
  File "F:\dxr\Myproject\work\home_application\views.py", line 43, in render_json
    return HttpResponse(json.dumps(res_dict),content_type='application/json')
NameError: name 'json' is not defined
], 请求URL->[/sayhello/], 请求方法->[POST] 请求参数->[{"input": "Hello"}] 

ERROR [2020-08-11 14:01:20] F:\dxr\Myproject\work\blueapps\core\exceptions\middleware.py 70 process_exception 18876 20404 
 	 捕获未处理异常,异常具体堆栈->[Traceback (most recent call last):
  File "D:\python\lib\site-packages\django\core\handlers\base.py", line 113, in _get_response
    response = wrapped_callback(request, *callback_args, **callback_kwargs)
  File "F:\dxr\Myproject\work\home_application\views.py", line 50, in say_hello
    return render_json(res)
  File "F:\dxr\Myproject\work\home_application\views.py", line 44, in render_json
    return HttpResponse(json_dumps(res_dict),content_type='application/json')
NameError: name 'json_dumps' is not defined
], 请求URL->[/sayhello/], 请求方法->[POST] 请求参数->[{"input": "Hello"}] 

ERROR [2020-08-11 14:06:03] F:\dxr\Myproject\work\blueapps\core\exceptions\middleware.py 70 process_exception 19952 19224 
 	 捕获未处理异常,异常具体堆栈->[Traceback (most recent call last):
  File "D:\python\lib\site-packages\django\template\base.py", line 470, in parse
    compile_func = self.tags[command]
KeyError: 'trans'

During handling of the above exception, another exception occurred:

Traceback (most recent call last):
  File "D:\python\lib\site-packages\django\core\handlers\base.py", line 113, in _get_response
    response = wrapped_callback(request, *callback_args, **callback_kwargs)
  File "F:\dxr\Myproject\work\home_application\views.py", line 41, in helloworld
    return render(request, 'home_application/helloworld.html')
  File "D:\python\lib\site-packages\django\shortcuts.py", line 36, in render
    content = loader.render_to_string(template_name, context, request, using=using)
  File "D:\python\lib\site-packages\django\template\loader.py", line 61, in render_to_string
    template = get_template(template_name, using=using)
  File "D:\python\lib\site-packages\django\template\loader.py", line 15, in get_template
    return engine.get_template(template_name)
  File "D:\python\lib\site-packages\django\template\backends\django.py", line 34, in get_template
    return Template(self.engine.get_template(template_name), self)
  File "D:\python\lib\site-packages\django\template\engine.py", line 143, in get_template
    template, origin = self.find_template(template_name)
  File "D:\python\lib\site-packages\django\template\engine.py", line 125, in find_template
    template = loader.get_template(name, skip=skip)
  File "D:\python\lib\site-packages\django\template\loaders\base.py", line 30, in get_template
    contents, origin, origin.template_name, self.engine,
  File "D:\python\lib\site-packages\django\template\base.py", line 156, in __init__
    self.nodelist = self.compile_nodelist()
  File "D:\python\lib\site-packages\django\template\base.py", line 194, in compile_nodelist
    return parser.parse()
  File "D:\python\lib\site-packages\django\template\base.py", line 478, in parse
    raise self.error(token, e)
  File "D:\python\lib\site-packages\django\template\base.py", line 476, in parse
    compiled_result = compile_func(self, token)
  File "D:\python\lib\site-packages\django\template\loader_tags.py", line 209, in do_block
    nodelist = parser.parse(('endblock',))
  File "D:\python\lib\site-packages\django\template\base.py", line 472, in parse
    self.invalid_block_tag(token, command, parse_until)
  File "D:\python\lib\site-packages\django\template\base.py", line 528, in invalid_block_tag
    get_text_list(["'%s'" % p for p in parse_until], 'or'),
django.template.exceptions.TemplateSyntaxError: Invalid block tag on line 2: 'trans', expected 'endblock'. Did you forget to register or load this tag?
], 请求URL->[/helloworld/], 请求方法->[GET] 请求参数->[{}] 

ERROR [2020-08-11 14:07:00] F:\dxr\Myproject\work\blueapps\core\exceptions\middleware.py 70 process_exception 16420 7616 
 	 捕获未处理异常,异常具体堆栈->[Traceback (most recent call last):
  File "D:\python\lib\site-packages\django\core\handlers\base.py", line 113, in _get_response
    response = wrapped_callback(request, *callback_args, **callback_kwargs)
  File "F:\dxr\Myproject\work\home_application\views.py", line 41, in helloworld
    return render(request, 'home_application/helloworld.html')
  File "D:\python\lib\site-packages\django\shortcuts.py", line 36, in render
    content = loader.render_to_string(template_name, context, request, using=using)
  File "D:\python\lib\site-packages\django\template\loader.py", line 62, in render_to_string
    return template.render(context, request)
  File "D:\python\lib\site-packages\django\template\backends\django.py", line 61, in render
    return self.template.render(context)
  File "D:\python\lib\site-packages\django\template\base.py", line 171, in render
    return self._render(context)
  File "D:\python\lib\site-packages\django\template\base.py", line 163, in _render
    return self.nodelist.render(context)
  File "D:\python\lib\site-packages\django\template\base.py", line 937, in render
    bit = node.render_annotated(context)
  File "D:\python\lib\site-packages\django\template\base.py", line 904, in render_annotated
    return self.render(context)
  File "D:\python\lib\site-packages\django\template\loader_tags.py", line 53, in render
    result = self.nodelist.render(context)
  File "D:\python\lib\site-packages\django\template\base.py", line 937, in render
    bit = node.render_annotated(context)
  File "D:\python\lib\site-packages\django\template\base.py", line 904, in render_annotated
    return self.render(context)
  File "D:\python\lib\site-packages\django\template\base.py", line 987, in render
    output = self.filter_expression.resolve(context)
  File "D:\python\lib\site-packages\django\template\base.py", line 671, in resolve
    obj = self.var.resolve(context)
  File "D:\python\lib\site-packages\django\template\base.py", line 796, in resolve
    value = self._resolve_lookup(context)
  File "D:\python\lib\site-packages\django\template\base.py", line 858, in _resolve_lookup
    current = current()
  File "D:\python\lib\site-packages\django\template\loader_tags.py", line 71, in super
    "{{ block.super }} in a base template?" % self.__class__.__name__
django.template.exceptions.TemplateSyntaxError: 'BlockNode' object has no attribute 'context'. Did you use {{ block.super }} in a base template?
], 请求URL->[/helloworld/], 请求方法->[GET] 请求参数->[{}] 

ERROR [2020-08-11 14:07:04] F:\dxr\Myproject\work\blueapps\core\exceptions\middleware.py 70 process_exception 16420 10844 
 	 捕获未处理异常,异常具体堆栈->[Traceback (most recent call last):
  File "D:\python\lib\site-packages\django\core\handlers\base.py", line 113, in _get_response
    response = wrapped_callback(request, *callback_args, **callback_kwargs)
  File "F:\dxr\Myproject\work\home_application\views.py", line 41, in helloworld
    return render(request, 'home_application/helloworld.html')
  File "D:\python\lib\site-packages\django\shortcuts.py", line 36, in render
    content = loader.render_to_string(template_name, context, request, using=using)
  File "D:\python\lib\site-packages\django\template\loader.py", line 62, in render_to_string
    return template.render(context, request)
  File "D:\python\lib\site-packages\django\template\backends\django.py", line 61, in render
    return self.template.render(context)
  File "D:\python\lib\site-packages\django\template\base.py", line 171, in render
    return self._render(context)
  File "D:\python\lib\site-packages\django\template\base.py", line 163, in _render
    return self.nodelist.render(context)
  File "D:\python\lib\site-packages\django\template\base.py", line 937, in render
    bit = node.render_annotated(context)
  File "D:\python\lib\site-packages\django\template\base.py", line 904, in render_annotated
    return self.render(context)
  File "D:\python\lib\site-packages\django\template\loader_tags.py", line 53, in render
    result = self.nodelist.render(context)
  File "D:\python\lib\site-packages\django\template\base.py", line 937, in render
    bit = node.render_annotated(context)
  File "D:\python\lib\site-packages\django\template\base.py", line 904, in render_annotated
    return self.render(context)
  File "D:\python\lib\site-packages\django\template\base.py", line 987, in render
    output = self.filter_expression.resolve(context)
  File "D:\python\lib\site-packages\django\template\base.py", line 671, in resolve
    obj = self.var.resolve(context)
  File "D:\python\lib\site-packages\django\template\base.py", line 796, in resolve
    value = self._resolve_lookup(context)
  File "D:\python\lib\site-packages\django\template\base.py", line 858, in _resolve_lookup
    current = current()
  File "D:\python\lib\site-packages\django\template\loader_tags.py", line 71, in super
    "{{ block.super }} in a base template?" % self.__class__.__name__
django.template.exceptions.TemplateSyntaxError: 'BlockNode' object has no attribute 'context'. Did you use {{ block.super }} in a base template?
], 请求URL->[/helloworld/], 请求方法->[GET] 请求参数->[{}] 

ERROR [2020-08-12 09:39:10] F:\dxr\Myproject\work\blueapps\core\exceptions\middleware.py 70 process_exception 9752 9456 
 	 捕获未处理异常,异常具体堆栈->[Traceback (most recent call last):
  File "D:\python\lib\site-packages\django\core\handlers\base.py", line 113, in _get_response
    response = wrapped_callback(request, *callback_args, **callback_kwargs)
  File "F:\dxr\Myproject\work\meeting\views.py", line 9, in meeting
    return render(request, '/meeting/meeting.html')
  File "D:\python\lib\site-packages\django\shortcuts.py", line 36, in render
    content = loader.render_to_string(template_name, context, request, using=using)
  File "D:\python\lib\site-packages\django\template\loader.py", line 61, in render_to_string
    template = get_template(template_name, using=using)
  File "D:\python\lib\site-packages\django\template\loader.py", line 19, in get_template
    raise TemplateDoesNotExist(template_name, chain=chain)
django.template.exceptions.TemplateDoesNotExist: /meeting/meeting.html
], 请求URL->[/meeting/], 请求方法->[GET] 请求参数->[{}] 

ERROR [2020-08-12 09:39:49] F:\dxr\Myproject\work\blueapps\core\exceptions\middleware.py 70 process_exception 13456 13928 
 	 捕获未处理异常,异常具体堆栈->[Traceback (most recent call last):
  File "D:\python\lib\site-packages\django\core\handlers\base.py", line 113, in _get_response
    response = wrapped_callback(request, *callback_args, **callback_kwargs)
  File "F:\dxr\Myproject\work\meeting\views.py", line 9, in meeting
    return render(request, 'meeting.html')
  File "D:\python\lib\site-packages\django\shortcuts.py", line 36, in render
    content = loader.render_to_string(template_name, context, request, using=using)
  File "D:\python\lib\site-packages\django\template\loader.py", line 61, in render_to_string
    template = get_template(template_name, using=using)
  File "D:\python\lib\site-packages\django\template\loader.py", line 19, in get_template
    raise TemplateDoesNotExist(template_name, chain=chain)
django.template.exceptions.TemplateDoesNotExist: meeting.html
], 请求URL->[/meeting/], 请求方法->[GET] 请求参数->[{}] 

ERROR [2020-08-12 09:40:48] F:\dxr\Myproject\work\blueapps\core\exceptions\middleware.py 70 process_exception 8620 12576 
 	 捕获未处理异常,异常具体堆栈->[Traceback (most recent call last):
  File "D:\python\lib\site-packages\django\core\handlers\base.py", line 113, in _get_response
    response = wrapped_callback(request, *callback_args, **callback_kwargs)
  File "F:\dxr\Myproject\work\meeting\views.py", line 9, in meeting
    return render(request, 'meeting/meeting.html')
  File "D:\python\lib\site-packages\django\shortcuts.py", line 36, in render
    content = loader.render_to_string(template_name, context, request, using=using)
  File "D:\python\lib\site-packages\django\template\loader.py", line 61, in render_to_string
    template = get_template(template_name, using=using)
  File "D:\python\lib\site-packages\django\template\loader.py", line 19, in get_template
    raise TemplateDoesNotExist(template_name, chain=chain)
django.template.exceptions.TemplateDoesNotExist: meeting/meeting.html
], 请求URL->[/meeting/], 请求方法->[GET] 请求参数->[{}] 

ERROR [2020-08-12 09:55:50] F:\dxr\Myproject\work\blueapps\core\exceptions\middleware.py 70 process_exception 6668 2844 
 	 捕获未处理异常,异常具体堆栈->[Traceback (most recent call last):
  File "D:\python\lib\site-packages\django\db\backends\utils.py", line 84, in _execute
    return self.cursor.execute(sql, params)
  File "D:\python\lib\site-packages\django\db\backends\mysql\base.py", line 71, in execute
    return self.cursor.execute(query, args)
  File "D:\python\lib\site-packages\MySQLdb\cursors.py", line 209, in execute
    res = self._query(query)
  File "D:\python\lib\site-packages\MySQLdb\cursors.py", line 315, in _query
    db.query(q)
  File "D:\python\lib\site-packages\MySQLdb\connections.py", line 226, in query
    _mysql.connection.query(self, query)
MySQLdb._exceptions.ProgrammingError: (1146, "Table 'work.meeting_workrecord' doesn't exist")

The above exception was the direct cause of the following exception:

Traceback (most recent call last):
  File "D:\python\lib\site-packages\django\core\handlers\base.py", line 113, in _get_response
    response = wrapped_callback(request, *callback_args, **callback_kwargs)
  File "F:\dxr\Myproject\work\meeting\views.py", line 34, in records
    for index, record in enumerate(record_list):
  File "D:\python\lib\site-packages\django\db\models\query.py", line 274, in __iter__
    self._fetch_all()
  File "D:\python\lib\site-packages\django\db\models\query.py", line 1242, in _fetch_all
    self._result_cache = list(self._iterable_class(self))
  File "D:\python\lib\site-packages\django\db\models\query.py", line 55, in __iter__
    results = compiler.execute_sql(chunked_fetch=self.chunked_fetch, chunk_size=self.chunk_size)
  File "D:\python\lib\site-packages\django\db\models\sql\compiler.py", line 1100, in execute_sql
    cursor.execute(sql, params)
  File "D:\python\lib\site-packages\django\db\backends\utils.py", line 99, in execute
    return super().execute(sql, params)
  File "D:\python\lib\site-packages\django\db\backends\utils.py", line 67, in execute
    return self._execute_with_wrappers(sql, params, many=False, executor=self._execute)
  File "D:\python\lib\site-packages\django\db\backends\utils.py", line 76, in _execute_with_wrappers
    return executor(sql, params, many, context)
  File "D:\python\lib\site-packages\django\db\backends\utils.py", line 84, in _execute
    return self.cursor.execute(sql, params)
  File "D:\python\lib\site-packages\django\db\utils.py", line 89, in __exit__
    raise dj_exc_value.with_traceback(traceback) from exc_value
  File "D:\python\lib\site-packages\django\db\backends\utils.py", line 84, in _execute
    return self.cursor.execute(sql, params)
  File "D:\python\lib\site-packages\django\db\backends\mysql\base.py", line 71, in execute
    return self.cursor.execute(query, args)
  File "D:\python\lib\site-packages\MySQLdb\cursors.py", line 209, in execute
    res = self._query(query)
  File "D:\python\lib\site-packages\MySQLdb\cursors.py", line 315, in _query
    db.query(q)
  File "D:\python\lib\site-packages\MySQLdb\connections.py", line 226, in query
    _mysql.connection.query(self, query)
django.db.utils.ProgrammingError: (1146, "Table 'work.meeting_workrecord' doesn't exist")
], 请求URL->[/records/], 请求方法->[GET] 请求参数->[{}] 

ERROR [2020-08-12 10:03:29] F:\dxr\Myproject\work\blueapps\core\exceptions\middleware.py 70 process_exception 6668 11924 
 	 捕获未处理异常,异常具体堆栈->[Traceback (most recent call last):
  File "D:\python\lib\site-packages\django\db\backends\utils.py", line 84, in _execute
    return self.cursor.execute(sql, params)
  File "D:\python\lib\site-packages\django\db\backends\mysql\base.py", line 71, in execute
    return self.cursor.execute(query, args)
  File "D:\python\lib\site-packages\MySQLdb\cursors.py", line 209, in execute
    res = self._query(query)
  File "D:\python\lib\site-packages\MySQLdb\cursors.py", line 315, in _query
    db.query(q)
  File "D:\python\lib\site-packages\MySQLdb\connections.py", line 226, in query
    _mysql.connection.query(self, query)
MySQLdb._exceptions.ProgrammingError: (1146, "Table 'work.meeting_workrecord' doesn't exist")

The above exception was the direct cause of the following exception:

Traceback (most recent call last):
  File "D:\python\lib\site-packages\django\core\handlers\base.py", line 113, in _get_response
    response = wrapped_callback(request, *callback_args, **callback_kwargs)
  File "F:\dxr\Myproject\work\meeting\views.py", line 34, in records
    for index, record in enumerate(record_list):
  File "D:\python\lib\site-packages\django\db\models\query.py", line 274, in __iter__
    self._fetch_all()
  File "D:\python\lib\site-packages\django\db\models\query.py", line 1242, in _fetch_all
    self._result_cache = list(self._iterable_class(self))
  File "D:\python\lib\site-packages\django\db\models\query.py", line 55, in __iter__
    results = compiler.execute_sql(chunked_fetch=self.chunked_fetch, chunk_size=self.chunk_size)
  File "D:\python\lib\site-packages\django\db\models\sql\compiler.py", line 1100, in execute_sql
    cursor.execute(sql, params)
  File "D:\python\lib\site-packages\django\db\backends\utils.py", line 99, in execute
    return super().execute(sql, params)
  File "D:\python\lib\site-packages\django\db\backends\utils.py", line 67, in execute
    return self._execute_with_wrappers(sql, params, many=False, executor=self._execute)
  File "D:\python\lib\site-packages\django\db\backends\utils.py", line 76, in _execute_with_wrappers
    return executor(sql, params, many, context)
  File "D:\python\lib\site-packages\django\db\backends\utils.py", line 84, in _execute
    return self.cursor.execute(sql, params)
  File "D:\python\lib\site-packages\django\db\utils.py", line 89, in __exit__
    raise dj_exc_value.with_traceback(traceback) from exc_value
  File "D:\python\lib\site-packages\django\db\backends\utils.py", line 84, in _execute
    return self.cursor.execute(sql, params)
  File "D:\python\lib\site-packages\django\db\backends\mysql\base.py", line 71, in execute
    return self.cursor.execute(query, args)
  File "D:\python\lib\site-packages\MySQLdb\cursors.py", line 209, in execute
    res = self._query(query)
  File "D:\python\lib\site-packages\MySQLdb\cursors.py", line 315, in _query
    db.query(q)
  File "D:\python\lib\site-packages\MySQLdb\connections.py", line 226, in query
    _mysql.connection.query(self, query)
django.db.utils.ProgrammingError: (1146, "Table 'work.meeting_workrecord' doesn't exist")
], 请求URL->[/records/], 请求方法->[GET] 请求参数->[{}] 

ERROR [2020-08-12 10:12:12] F:\dxr\Myproject\work\blueapps\core\exceptions\middleware.py 70 process_exception 10520 8592 
 	 捕获未处理异常,异常具体堆栈->[Traceback (most recent call last):
  File "D:\python\lib\site-packages\django\db\backends\utils.py", line 84, in _execute
    return self.cursor.execute(sql, params)
  File "D:\python\lib\site-packages\django\db\backends\mysql\base.py", line 71, in execute
    return self.cursor.execute(query, args)
  File "D:\python\lib\site-packages\MySQLdb\cursors.py", line 209, in execute
    res = self._query(query)
  File "D:\python\lib\site-packages\MySQLdb\cursors.py", line 315, in _query
    db.query(q)
  File "D:\python\lib\site-packages\MySQLdb\connections.py", line 226, in query
    _mysql.connection.query(self, query)
MySQLdb._exceptions.ProgrammingError: (1146, "Table 'work.meeting_workrecord' doesn't exist")

The above exception was the direct cause of the following exception:

Traceback (most recent call last):
  File "D:\python\lib\site-packages\django\core\handlers\base.py", line 113, in _get_response
    response = wrapped_callback(request, *callback_args, **callback_kwargs)
  File "F:\dxr\Myproject\work\meeting\views.py", line 34, in records
    for index, record in enumerate(record_list):
  File "D:\python\lib\site-packages\django\db\models\query.py", line 274, in __iter__
    self._fetch_all()
  File "D:\python\lib\site-packages\django\db\models\query.py", line 1242, in _fetch_all
    self._result_cache = list(self._iterable_class(self))
  File "D:\python\lib\site-packages\django\db\models\query.py", line 55, in __iter__
    results = compiler.execute_sql(chunked_fetch=self.chunked_fetch, chunk_size=self.chunk_size)
  File "D:\python\lib\site-packages\django\db\models\sql\compiler.py", line 1100, in execute_sql
    cursor.execute(sql, params)
  File "D:\python\lib\site-packages\django\db\backends\utils.py", line 99, in execute
    return super().execute(sql, params)
  File "D:\python\lib\site-packages\django\db\backends\utils.py", line 67, in execute
    return self._execute_with_wrappers(sql, params, many=False, executor=self._execute)
  File "D:\python\lib\site-packages\django\db\backends\utils.py", line 76, in _execute_with_wrappers
    return executor(sql, params, many, context)
  File "D:\python\lib\site-packages\django\db\backends\utils.py", line 84, in _execute
    return self.cursor.execute(sql, params)
  File "D:\python\lib\site-packages\django\db\utils.py", line 89, in __exit__
    raise dj_exc_value.with_traceback(traceback) from exc_value
  File "D:\python\lib\site-packages\django\db\backends\utils.py", line 84, in _execute
    return self.cursor.execute(sql, params)
  File "D:\python\lib\site-packages\django\db\backends\mysql\base.py", line 71, in execute
    return self.cursor.execute(query, args)
  File "D:\python\lib\site-packages\MySQLdb\cursors.py", line 209, in execute
    res = self._query(query)
  File "D:\python\lib\site-packages\MySQLdb\cursors.py", line 315, in _query
    db.query(q)
  File "D:\python\lib\site-packages\MySQLdb\connections.py", line 226, in query
    _mysql.connection.query(self, query)
django.db.utils.ProgrammingError: (1146, "Table 'work.meeting_workrecord' doesn't exist")
], 请求URL->[/records/], 请求方法->[GET] 请求参数->[{}] 

ERROR [2020-08-12 10:29:23] F:\dxr\Myproject\work\blueapps\core\exceptions\middleware.py 70 process_exception 15592 7644 
 	 捕获未处理异常,异常具体堆栈->[Traceback (most recent call last):
  File "D:\python\lib\site-packages\django\db\backends\utils.py", line 84, in _execute
    return self.cursor.execute(sql, params)
  File "D:\python\lib\site-packages\django\db\backends\mysql\base.py", line 71, in execute
    return self.cursor.execute(query, args)
  File "D:\python\lib\site-packages\MySQLdb\cursors.py", line 209, in execute
    res = self._query(query)
  File "D:\python\lib\site-packages\MySQLdb\cursors.py", line 315, in _query
    db.query(q)
  File "D:\python\lib\site-packages\MySQLdb\connections.py", line 226, in query
    _mysql.connection.query(self, query)
MySQLdb._exceptions.ProgrammingError: (1146, "Table 'work.meeting_workrecord' doesn't exist")

The above exception was the direct cause of the following exception:

Traceback (most recent call last):
  File "D:\python\lib\site-packages\django\core\handlers\base.py", line 113, in _get_response
    response = wrapped_callback(request, *callback_args, **callback_kwargs)
  File "F:\dxr\Myproject\work\meeting\views.py", line 34, in records
    for index, record in enumerate(record_list):
  File "D:\python\lib\site-packages\django\db\models\query.py", line 274, in __iter__
    self._fetch_all()
  File "D:\python\lib\site-packages\django\db\models\query.py", line 1242, in _fetch_all
    self._result_cache = list(self._iterable_class(self))
  File "D:\python\lib\site-packages\django\db\models\query.py", line 55, in __iter__
    results = compiler.execute_sql(chunked_fetch=self.chunked_fetch, chunk_size=self.chunk_size)
  File "D:\python\lib\site-packages\django\db\models\sql\compiler.py", line 1100, in execute_sql
    cursor.execute(sql, params)
  File "D:\python\lib\site-packages\django\db\backends\utils.py", line 99, in execute
    return super().execute(sql, params)
  File "D:\python\lib\site-packages\django\db\backends\utils.py", line 67, in execute
    return self._execute_with_wrappers(sql, params, many=False, executor=self._execute)
  File "D:\python\lib\site-packages\django\db\backends\utils.py", line 76, in _execute_with_wrappers
    return executor(sql, params, many, context)
  File "D:\python\lib\site-packages\django\db\backends\utils.py", line 84, in _execute
    return self.cursor.execute(sql, params)
  File "D:\python\lib\site-packages\django\db\utils.py", line 89, in __exit__
    raise dj_exc_value.with_traceback(traceback) from exc_value
  File "D:\python\lib\site-packages\django\db\backends\utils.py", line 84, in _execute
    return self.cursor.execute(sql, params)
  File "D:\python\lib\site-packages\django\db\backends\mysql\base.py", line 71, in execute
    return self.cursor.execute(query, args)
  File "D:\python\lib\site-packages\MySQLdb\cursors.py", line 209, in execute
    res = self._query(query)
  File "D:\python\lib\site-packages\MySQLdb\cursors.py", line 315, in _query
    db.query(q)
  File "D:\python\lib\site-packages\MySQLdb\connections.py", line 226, in query
    _mysql.connection.query(self, query)
django.db.utils.ProgrammingError: (1146, "Table 'work.meeting_workrecord' doesn't exist")
], 请求URL->[/records/], 请求方法->[GET] 请求参数->[{}] 

ERROR [2020-08-12 10:43:37] F:\dxr\Myproject\work\blueapps\core\exceptions\middleware.py 70 process_exception 6464 15984 
 	 捕获未处理异常,异常具体堆栈->[Traceback (most recent call last):
  File "D:\python\lib\site-packages\django\core\handlers\base.py", line 113, in _get_response
    response = wrapped_callback(request, *callback_args, **callback_kwargs)
  File "F:\dxr\Myproject\work\home_application\views.py", line 79, in records
    record_list = workRecord.objects.all().order_by('-id')
NameError: name 'workRecord' is not defined
], 请求URL->[/records/], 请求方法->[GET] 请求参数->[{}] 

ERROR [2020-08-12 10:48:03] F:\dxr\Myproject\work\blueapps\core\exceptions\middleware.py 70 process_exception 6464 14680 
 	 捕获未处理异常,异常具体堆栈->[Traceback (most recent call last):
  File "D:\python\lib\site-packages\django\core\handlers\base.py", line 113, in _get_response
    response = wrapped_callback(request, *callback_args, **callback_kwargs)
  File "F:\dxr\Myproject\work\home_application\views.py", line 79, in records
    record_list = workRecord.objects.all().order_by('-id')
NameError: name 'workRecord' is not defined
], 请求URL->[/records/], 请求方法->[GET] 请求参数->[{}] 

ERROR [2020-08-12 10:48:07] F:\dxr\Myproject\work\blueapps\core\exceptions\middleware.py 70 process_exception 6464 14680 
 	 捕获未处理异常,异常具体堆栈->[Traceback (most recent call last):
  File "D:\python\lib\site-packages\django\core\handlers\base.py", line 113, in _get_response
    response = wrapped_callback(request, *callback_args, **callback_kwargs)
  File "F:\dxr\Myproject\work\home_application\views.py", line 70, in save_record
    result = workRecord.objects.save_record(data)
NameError: name 'workRecord' is not defined
], 请求URL->[/save_record/], 请求方法->[POST] 请求参数->[{"theme": "", "content": ""}] 

ERROR [2020-08-12 10:48:08] F:\dxr\Myproject\work\blueapps\core\exceptions\middleware.py 70 process_exception 6464 14680 
 	 捕获未处理异常,异常具体堆栈->[Traceback (most recent call last):
  File "D:\python\lib\site-packages\django\core\handlers\base.py", line 113, in _get_response
    response = wrapped_callback(request, *callback_args, **callback_kwargs)
  File "F:\dxr\Myproject\work\home_application\views.py", line 70, in save_record
    result = workRecord.objects.save_record(data)
NameError: name 'workRecord' is not defined
], 请求URL->[/save_record/], 请求方法->[POST] 请求参数->[{"theme": "", "content": ""}] 

ERROR [2020-08-12 10:50:46] F:\dxr\Myproject\work\blueapps\core\exceptions\middleware.py 70 process_exception 8884 2784 
 	 捕获未处理异常,异常具体堆栈->[Traceback (most recent call last):
  File "D:\python\lib\site-packages\django\core\handlers\base.py", line 113, in _get_response
    response = wrapped_callback(request, *callback_args, **callback_kwargs)
  File "F:\dxr\Myproject\work\home_application\views.py", line 80, in records
    record_list = workRecord.objects.all().order_by('-id')
NameError: name 'workRecord' is not defined
], 请求URL->[/records/], 请求方法->[GET] 请求参数->[{}] 

ERROR [2020-08-12 10:52:48] F:\dxr\Myproject\work\blueapps\core\exceptions\middleware.py 70 process_exception 15852 784 
 	 捕获未处理异常,异常具体堆栈->[Traceback (most recent call last):
  File "D:\python\lib\site-packages\django\core\handlers\base.py", line 113, in _get_response
    response = wrapped_callback(request, *callback_args, **callback_kwargs)
  File "F:\dxr\Myproject\work\home_application\views.py", line 80, in records
    record_list = workRecord.objects.all().order_by('-id')
NameError: name 'workRecord' is not defined
], 请求URL->[/records/], 请求方法->[GET] 请求参数->[{}] 

ERROR [2020-08-12 10:56:34] F:\dxr\Myproject\work\blueapps\core\exceptions\middleware.py 70 process_exception 6796 3984 
 	 捕获未处理异常,异常具体堆栈->[Traceback (most recent call last):
  File "D:\python\lib\site-packages\django\core\handlers\base.py", line 113, in _get_response
    response = wrapped_callback(request, *callback_args, **callback_kwargs)
  File "F:\dxr\Myproject\work\home_application\views.py", line 80, in records
    record_list = workRecord.objects.all().order_by('-id')
NameError: name 'workRecord' is not defined
], 请求URL->[/records/], 请求方法->[GET] 请求参数->[{}] 

ERROR [2020-08-12 11:06:25] F:\dxr\Myproject\work\blueapps\core\exceptions\middleware.py 70 process_exception 7184 8540 
 	 捕获未处理异常,异常具体堆栈->[Traceback (most recent call last):
  File "D:\python\lib\site-packages\django\core\handlers\base.py", line 113, in _get_response
    response = wrapped_callback(request, *callback_args, **callback_kwargs)
  File "F:\dxr\Myproject\work\home_application\views.py", line 80, in records
    record_list = workRecord.objects.all().order_by('-id')
NameError: name 'workRecord' is not defined
], 请求URL->[/records/], 请求方法->[GET] 请求参数->[{}] 

ERROR [2020-08-12 11:10:32] F:\dxr\Myproject\work\blueapps\core\exceptions\middleware.py 70 process_exception 7184 7736 
 	 捕获未处理异常,异常具体堆栈->[Traceback (most recent call last):
  File "D:\python\lib\site-packages\django\core\handlers\base.py", line 113, in _get_response
    response = wrapped_callback(request, *callback_args, **callback_kwargs)
  File "F:\dxr\Myproject\work\home_application\views.py", line 80, in records
    record_list = workRecord.objects.all().order_by('-id')
NameError: name 'workRecord' is not defined
], 请求URL->[/records/], 请求方法->[GET] 请求参数->[{}] 

ERROR [2020-08-12 11:16:31] F:\dxr\Myproject\work\blueapps\core\exceptions\middleware.py 70 process_exception 6420 17828 
 	 捕获未处理异常,异常具体堆栈->[Traceback (most recent call last):
  File "D:\python\lib\site-packages\django\core\handlers\base.py", line 113, in _get_response
    response = wrapped_callback(request, *callback_args, **callback_kwargs)
  File "F:\dxr\Myproject\work\home_application\views.py", line 80, in records
    record_list = workRecord.objects.all().order_by('-id')
NameError: name 'workRecord' is not defined
], 请求URL->[/records/], 请求方法->[GET] 请求参数->[{}] 

ERROR [2020-08-12 11:23:44] F:\dxr\Myproject\work\blueapps\core\exceptions\middleware.py 70 process_exception 17152 17752 
 	 捕获未处理异常,异常具体堆栈->[Traceback (most recent call last):
  File "D:\python\lib\site-packages\django\core\handlers\base.py", line 113, in _get_response
    response = wrapped_callback(request, *callback_args, **callback_kwargs)
  File "F:\dxr\Myproject\work\home_application\views.py", line 80, in records
    record_list = workRecord.objects.all().order_by('-id')
NameError: name 'workRecord' is not defined
], 请求URL->[/records/], 请求方法->[GET] 请求参数->[{}] 

ERROR [2020-08-12 11:24:39] F:\dxr\Myproject\work\blueapps\core\exceptions\middleware.py 70 process_exception 17152 17752 
 	 捕获未处理异常,异常具体堆栈->[Traceback (most recent call last):
  File "D:\python\lib\site-packages\django\core\handlers\base.py", line 113, in _get_response
    response = wrapped_callback(request, *callback_args, **callback_kwargs)
  File "F:\dxr\Myproject\work\home_application\views.py", line 80, in records
    record_list = workRecord.objects.all().order_by('-id')
NameError: name 'workRecord' is not defined
], 请求URL->[/records/], 请求方法->[GET] 请求参数->[{}] 

ERROR [2020-08-12 11:28:15] F:\dxr\Myproject\work\blueapps\core\exceptions\middleware.py 70 process_exception 17452 18260 
 	 捕获未处理异常,异常具体堆栈->[Traceback (most recent call last):
  File "D:\python\lib\site-packages\django\db\backends\utils.py", line 84, in _execute
    return self.cursor.execute(sql, params)
  File "D:\python\lib\site-packages\django\db\backends\mysql\base.py", line 71, in execute
    return self.cursor.execute(query, args)
  File "D:\python\lib\site-packages\MySQLdb\cursors.py", line 209, in execute
    res = self._query(query)
  File "D:\python\lib\site-packages\MySQLdb\cursors.py", line 315, in _query
    db.query(q)
  File "D:\python\lib\site-packages\MySQLdb\connections.py", line 226, in query
    _mysql.connection.query(self, query)
MySQLdb._exceptions.ProgrammingError: (1146, "Table 'work.home_application_workrecord' doesn't exist")

The above exception was the direct cause of the following exception:

Traceback (most recent call last):
  File "D:\python\lib\site-packages\django\core\handlers\base.py", line 113, in _get_response
    response = wrapped_callback(request, *callback_args, **callback_kwargs)
  File "F:\dxr\Myproject\work\home_application\views.py", line 82, in records
    for index, record in enumerate(record_list):
  File "D:\python\lib\site-packages\django\db\models\query.py", line 274, in __iter__
    self._fetch_all()
  File "D:\python\lib\site-packages\django\db\models\query.py", line 1242, in _fetch_all
    self._result_cache = list(self._iterable_class(self))
  File "D:\python\lib\site-packages\django\db\models\query.py", line 55, in __iter__
    results = compiler.execute_sql(chunked_fetch=self.chunked_fetch, chunk_size=self.chunk_size)
  File "D:\python\lib\site-packages\django\db\models\sql\compiler.py", line 1100, in execute_sql
    cursor.execute(sql, params)
  File "D:\python\lib\site-packages\django\db\backends\utils.py", line 99, in execute
    return super().execute(sql, params)
  File "D:\python\lib\site-packages\django\db\backends\utils.py", line 67, in execute
    return self._execute_with_wrappers(sql, params, many=False, executor=self._execute)
  File "D:\python\lib\site-packages\django\db\backends\utils.py", line 76, in _execute_with_wrappers
    return executor(sql, params, many, context)
  File "D:\python\lib\site-packages\django\db\backends\utils.py", line 84, in _execute
    return self.cursor.execute(sql, params)
  File "D:\python\lib\site-packages\django\db\utils.py", line 89, in __exit__
    raise dj_exc_value.with_traceback(traceback) from exc_value
  File "D:\python\lib\site-packages\django\db\backends\utils.py", line 84, in _execute
    return self.cursor.execute(sql, params)
  File "D:\python\lib\site-packages\django\db\backends\mysql\base.py", line 71, in execute
    return self.cursor.execute(query, args)
  File "D:\python\lib\site-packages\MySQLdb\cursors.py", line 209, in execute
    res = self._query(query)
  File "D:\python\lib\site-packages\MySQLdb\cursors.py", line 315, in _query
    db.query(q)
  File "D:\python\lib\site-packages\MySQLdb\connections.py", line 226, in query
    _mysql.connection.query(self, query)
django.db.utils.ProgrammingError: (1146, "Table 'work.home_application_workrecord' doesn't exist")
], 请求URL->[/records/], 请求方法->[GET] 请求参数->[{}] 

ERROR [2020-08-14 10:52:24] F:\dxr\Myproject\work\blueapps\core\exceptions\middleware.py 70 process_exception 4772 8128 
 	 捕获未处理异常,异常具体堆栈->[Traceback (most recent call last):
  File "D:\python\lib\site-packages\django\core\handlers\base.py", line 113, in _get_response
    response = wrapped_callback(request, *callback_args, **callback_kwargs)
  File "F:\dxr\Myproject\work\home_application\views.py", line 143, in export_excel
    for i in UserTable.objects.all():
NameError: name 'UserTable' is not defined
], 请求URL->[/export_excel/], 请求方法->[GET] 请求参数->[{}] 

ERROR [2020-08-14 10:54:24] F:\dxr\Myproject\work\blueapps\core\exceptions\middleware.py 70 process_exception 14216 17024 
 	 捕获未处理异常,异常具体堆栈->[Traceback (most recent call last):
  File "D:\python\lib\site-packages\django\core\handlers\base.py", line 113, in _get_response
    response = wrapped_callback(request, *callback_args, **callback_kwargs)
  File "F:\dxr\Myproject\work\home_application\views.py", line 145, in export_excel
    pri_time = i.pri_date.strftime('%Y-%m-%d')
AttributeError: 'workRecord' object has no attribute 'pri_date'
], 请求URL->[/export_excel/], 请求方法->[GET] 请求参数->[{}] 

ERROR [2020-08-14 10:54:47] F:\dxr\Myproject\work\blueapps\core\exceptions\middleware.py 70 process_exception 10416 7692 
 	 捕获未处理异常,异常具体堆栈->[Traceback (most recent call last):
  File "D:\python\lib\site-packages\django\core\handlers\base.py", line 113, in _get_response
    response = wrapped_callback(request, *callback_args, **callback_kwargs)
  File "F:\dxr\Myproject\work\home_application\views.py", line 145, in export_excel
    sheet.write(data_row,0,i.index)
AttributeError: 'workRecord' object has no attribute 'index'
], 请求URL->[/export_excel/], 请求方法->[GET] 请求参数->[{}] 

ERROR [2020-08-14 15:52:35] F:\dxr\Myproject\work\blueapps\core\exceptions\middleware.py 70 process_exception 15280 20760 
 	 捕获未处理异常,异常具体堆栈->[Traceback (most recent call last):
  File "D:\python\lib\site-packages\django\utils\datastructures.py", line 78, in __getitem__
    list_ = super().__getitem__(key)
KeyError: 'my_file'

During handling of the above exception, another exception occurred:

Traceback (most recent call last):
  File "D:\python\lib\site-packages\django\core\handlers\base.py", line 113, in _get_response
    response = wrapped_callback(request, *callback_args, **callback_kwargs)
  File "F:\dxr\Myproject\work\home_application\views.py", line 170, in excel_upload
    f = request.FILES['my_file']
  File "D:\python\lib\site-packages\django\utils\datastructures.py", line 80, in __getitem__
    raise MultiValueDictKeyError(key)
django.utils.datastructures.MultiValueDictKeyError: 'my_file'
], 请求URL->[/excel_upload/], 请求方法->[POST] 请求参数->[{"csrfmiddlewaretoken": "0bRxtz3xkFbWf1aDrL4WeLfcUOBZjcL7wxgNZfrVcwoSJ2NLwomxezk789RtHTpA", "my_file": ""}] 

ERROR [2020-08-14 15:54:10] F:\dxr\Myproject\work\blueapps\core\exceptions\middleware.py 70 process_exception 20208 18888 
 	 捕获未处理异常,异常具体堆栈->[Traceback (most recent call last):
  File "D:\python\lib\site-packages\django\utils\datastructures.py", line 78, in __getitem__
    list_ = super().__getitem__(key)
KeyError: 'mfile'

During handling of the above exception, another exception occurred:

Traceback (most recent call last):
  File "D:\python\lib\site-packages\django\core\handlers\base.py", line 113, in _get_response
    response = wrapped_callback(request, *callback_args, **callback_kwargs)
  File "F:\dxr\Myproject\work\home_application\views.py", line 170, in excel_upload
    f = request.FILES['mfile']
  File "D:\python\lib\site-packages\django\utils\datastructures.py", line 80, in __getitem__
    raise MultiValueDictKeyError(key)
django.utils.datastructures.MultiValueDictKeyError: 'mfile'
], 请求URL->[/excel_upload/], 请求方法->[POST] 请求参数->[{"csrfmiddlewaretoken": "DRAWQyXguo0yUgPirhVmQwTsbcjQup2K9dZcmelEmfduohsqwUdXQkYnpxzkS6Gd", "mfile": ""}] 

ERROR [2020-08-14 15:54:30] F:\dxr\Myproject\work\blueapps\core\exceptions\middleware.py 70 process_exception 20208 18888 
 	 捕获未处理异常,异常具体堆栈->[Traceback (most recent call last):
  File "D:\python\lib\site-packages\django\utils\datastructures.py", line 78, in __getitem__
    list_ = super().__getitem__(key)
KeyError: 'mfile'

During handling of the above exception, another exception occurred:

Traceback (most recent call last):
  File "D:\python\lib\site-packages\django\core\handlers\base.py", line 113, in _get_response
    response = wrapped_callback(request, *callback_args, **callback_kwargs)
  File "F:\dxr\Myproject\work\home_application\views.py", line 170, in excel_upload
    f = request.FILES['mfile']
  File "D:\python\lib\site-packages\django\utils\datastructures.py", line 80, in __getitem__
    raise MultiValueDictKeyError(key)
django.utils.datastructures.MultiValueDictKeyError: 'mfile'
], 请求URL->[/excel_upload/], 请求方法->[POST] 请求参数->[{"csrfmiddlewaretoken": "DRAWQyXguo0yUgPirhVmQwTsbcjQup2K9dZcmelEmfduohsqwUdXQkYnpxzkS6Gd", "mfile": ""}] 

ERROR [2020-08-14 15:56:59] F:\dxr\Myproject\work\blueapps\core\exceptions\middleware.py 70 process_exception 2452 13876 
 	 捕获未处理异常,异常具体堆栈->[Traceback (most recent call last):
  File "D:\python\lib\site-packages\django\core\handlers\base.py", line 113, in _get_response
    response = wrapped_callback(request, *callback_args, **callback_kwargs)
  File "F:\dxr\Myproject\work\home_application\views.py", line 170, in excel_upload
    f = request.FILES.getlist['mfile']
TypeError: 'method' object is not subscriptable
], 请求URL->[/excel_upload/], 请求方法->[POST] 请求参数->[{"csrfmiddlewaretoken": "jTh6oJqfpM17eNWhDq4yzEd99NzVndiqPfGmUpODhDe3IOzpI3m9zsi4n8PpLUWT", "mfile": ""}] 

ERROR [2020-08-14 16:00:40] F:\dxr\Myproject\work\blueapps\core\exceptions\middleware.py 70 process_exception 1252 16276 
 	 捕获未处理异常,异常具体堆栈->[Traceback (most recent call last):
  File "D:\python\lib\site-packages\django\utils\datastructures.py", line 78, in __getitem__
    list_ = super().__getitem__(key)
KeyError: 'mfile'

During handling of the above exception, another exception occurred:

Traceback (most recent call last):
  File "D:\python\lib\site-packages\django\core\handlers\base.py", line 113, in _get_response
    response = wrapped_callback(request, *callback_args, **callback_kwargs)
  File "F:\dxr\Myproject\work\home_application\views.py", line 170, in excel_upload
    f = request.FILES['mfile']
  File "D:\python\lib\site-packages\django\utils\datastructures.py", line 80, in __getitem__
    raise MultiValueDictKeyError(key)
django.utils.datastructures.MultiValueDictKeyError: 'mfile'
], 请求URL->[/excel_upload/], 请求方法->[POST] 请求参数->[{"csrfmiddlewaretoken": "uKJ1y5LCwC2c9pHQPL1IjqEU9GQOQacz068h4L90otf8DqkYUojjjeJPn16ieRQ2", "mfile": ""}] 

ERROR [2020-08-14 16:07:38] F:\dxr\Myproject\work\blueapps\core\exceptions\middleware.py 70 process_exception 1252 20252 
 	 捕获未处理异常,异常具体堆栈->[Traceback (most recent call last):
  File "D:\python\lib\site-packages\django\utils\datastructures.py", line 78, in __getitem__
    list_ = super().__getitem__(key)
KeyError: 'mfile'

During handling of the above exception, another exception occurred:

Traceback (most recent call last):
  File "D:\python\lib\site-packages\django\core\handlers\base.py", line 113, in _get_response
    response = wrapped_callback(request, *callback_args, **callback_kwargs)
  File "F:\dxr\Myproject\work\home_application\views.py", line 170, in excel_upload
    f = request.FILES['mfile']
  File "D:\python\lib\site-packages\django\utils\datastructures.py", line 80, in __getitem__
    raise MultiValueDictKeyError(key)
django.utils.datastructures.MultiValueDictKeyError: 'mfile'
], 请求URL->[/excel_upload/], 请求方法->[POST] 请求参数->[{"csrfmiddlewaretoken": "uKJ1y5LCwC2c9pHQPL1IjqEU9GQOQacz068h4L90otf8DqkYUojjjeJPn16ieRQ2", "mfile": ""}] 

ERROR [2020-08-14 16:16:14] F:\dxr\Myproject\work\blueapps\core\exceptions\middleware.py 70 process_exception 1252 6136 
 	 捕获未处理异常,异常具体堆栈->[Traceback (most recent call last):
  File "D:\python\lib\site-packages\django\utils\datastructures.py", line 78, in __getitem__
    list_ = super().__getitem__(key)
KeyError: 'mfile'

During handling of the above exception, another exception occurred:

Traceback (most recent call last):
  File "D:\python\lib\site-packages\django\core\handlers\base.py", line 113, in _get_response
    response = wrapped_callback(request, *callback_args, **callback_kwargs)
  File "F:\dxr\Myproject\work\home_application\views.py", line 170, in excel_upload
    f = request.FILES['mfile']
  File "D:\python\lib\site-packages\django\utils\datastructures.py", line 80, in __getitem__
    raise MultiValueDictKeyError(key)
django.utils.datastructures.MultiValueDictKeyError: 'mfile'
], 请求URL->[/excel_upload/], 请求方法->[POST] 请求参数->[{"csrfmiddlewaretoken": "sQvfcbRWtkXoorzNGCK90SbUS6YxUcaxYcUvIRfklbakSscVLf2K0GgP6re1iTO0", "mfile": ""}] 

ERROR [2020-08-14 16:23:40] F:\dxr\Myproject\work\blueapps\core\exceptions\middleware.py 70 process_exception 13208 13160 
 	 捕获未处理异常,异常具体堆栈->[Traceback (most recent call last):
  File "D:\python\lib\site-packages\django\core\handlers\base.py", line 113, in _get_response
    response = wrapped_callback(request, *callback_args, **callback_kwargs)
  File "F:\dxr\Myproject\work\home_application\views.py", line 171, in excel_upload
    type_excel = f.name.split('.')[1]
AttributeError: 'str' object has no attribute 'name'
], 请求URL->[/excel_upload/], 请求方法->[POST] 请求参数->[{"csrfmiddlewaretoken": "sQvfcbRWtkXoorzNGCK90SbUS6YxUcaxYcUvIRfklbakSscVLf2K0GgP6re1iTO0", "mfile": ""}] 

ERROR [2020-08-14 16:24:15] F:\dxr\Myproject\work\blueapps\core\exceptions\middleware.py 70 process_exception 13208 13160 
 	 捕获未处理异常,异常具体堆栈->[Traceback (most recent call last):
  File "D:\python\lib\site-packages\django\core\handlers\base.py", line 113, in _get_response
    response = wrapped_callback(request, *callback_args, **callback_kwargs)
  File "F:\dxr\Myproject\work\home_application\views.py", line 171, in excel_upload
    type_excel = f.name.split('.')[1]
AttributeError: 'str' object has no attribute 'name'
], 请求URL->[/excel_upload/], 请求方法->[POST] 请求参数->[{"csrfmiddlewaretoken": "sQvfcbRWtkXoorzNGCK90SbUS6YxUcaxYcUvIRfklbakSscVLf2K0GgP6re1iTO0", "mfile": ""}] 

ERROR [2020-08-14 16:24:25] F:\dxr\Myproject\work\blueapps\core\exceptions\middleware.py 70 process_exception 13208 13160 
 	 捕获未处理异常,异常具体堆栈->[Traceback (most recent call last):
  File "D:\python\lib\site-packages\django\core\handlers\base.py", line 113, in _get_response
    response = wrapped_callback(request, *callback_args, **callback_kwargs)
  File "F:\dxr\Myproject\work\home_application\views.py", line 171, in excel_upload
    type_excel = f.name.split('.')[1]
AttributeError: 'str' object has no attribute 'name'
], 请求URL->[/excel_upload/], 请求方法->[POST] 请求参数->[{"csrfmiddlewaretoken": "sQvfcbRWtkXoorzNGCK90SbUS6YxUcaxYcUvIRfklbakSscVLf2K0GgP6re1iTO0", "mfile": ""}] 

ERROR [2020-08-14 16:24:29] F:\dxr\Myproject\work\blueapps\core\exceptions\middleware.py 70 process_exception 13208 13160 
 	 捕获未处理异常,异常具体堆栈->[Traceback (most recent call last):
  File "D:\python\lib\site-packages\django\core\handlers\base.py", line 113, in _get_response
    response = wrapped_callback(request, *callback_args, **callback_kwargs)
  File "F:\dxr\Myproject\work\home_application\views.py", line 171, in excel_upload
    type_excel = f.name.split('.')[1]
AttributeError: 'str' object has no attribute 'name'
], 请求URL->[/excel_upload/], 请求方法->[POST] 请求参数->[{"csrfmiddlewaretoken": "sQvfcbRWtkXoorzNGCK90SbUS6YxUcaxYcUvIRfklbakSscVLf2K0GgP6re1iTO0", "mfile": ""}] 

ERROR [2020-08-14 16:25:22] F:\dxr\Myproject\work\blueapps\core\exceptions\middleware.py 70 process_exception 7500 19884 
 	 捕获未处理异常,异常具体堆栈->[Traceback (most recent call last):
  File "D:\python\lib\site-packages\django\core\handlers\base.py", line 113, in _get_response
    response = wrapped_callback(request, *callback_args, **callback_kwargs)
  File "F:\dxr\Myproject\work\home_application\views.py", line 171, in excel_upload
    type_excel = f.name.split('.')[1]
AttributeError: 'NoneType' object has no attribute 'name'
], 请求URL->[/excel_upload/], 请求方法->[POST] 请求参数->[{"csrfmiddlewaretoken": "CYEhJghXcg0Gn2PL7viSszf8NY4hkfkz8k3xfWFl47dCR3sTc8Atsnk31jkLIWY2", "mfile": ""}] 

ERROR [2020-08-14 16:29:49] F:\dxr\Myproject\work\blueapps\core\exceptions\middleware.py 70 process_exception 13160 9952 
 	 捕获未处理异常,异常具体堆栈->[Traceback (most recent call last):
  File "D:\python\lib\site-packages\django\core\handlers\base.py", line 113, in _get_response
    response = wrapped_callback(request, *callback_args, **callback_kwargs)
  File "F:\dxr\Myproject\work\home_application\views.py", line 171, in excel_upload
    type_excel = f.name.split('.')[1]
AttributeError: 'NoneType' object has no attribute 'name'
], 请求URL->[/excel_upload/], 请求方法->[POST] 请求参数->[{"csrfmiddlewaretoken": "CYEhJghXcg0Gn2PL7viSszf8NY4hkfkz8k3xfWFl47dCR3sTc8Atsnk31jkLIWY2", "mfile": ""}] 

ERROR [2020-08-14 16:30:34] F:\dxr\Myproject\work\blueapps\core\exceptions\middleware.py 70 process_exception 13160 9952 
 	 捕获未处理异常,异常具体堆栈->[Traceback (most recent call last):
  File "F:\dxr\Myproject\work\home_application\views.py", line 179, in excel_upload
    with transaction.atomic():
NameError: name 'transaction' is not defined

During handling of the above exception, another exception occurred:

Traceback (most recent call last):
  File "D:\python\lib\site-packages\django\core\handlers\base.py", line 113, in _get_response
    response = wrapped_callback(request, *callback_args, **callback_kwargs)
  File "F:\dxr\Myproject\work\home_application\views.py", line 191, in excel_upload
    return JsonResponse({'msg':'出现错误....'})
NameError: name 'JsonResponse' is not defined
], 请求URL->[/excel_upload/], 请求方法->[POST] 请求参数->[{"csrfmiddlewaretoken": "B8RUwkqkCdZHbXDACs5prufMN3VaH9i17uga20OIu4cDFYgIH5n0rikH1obE5QWu"}] 

ERROR [2020-08-14 16:32:40] F:\dxr\Myproject\work\blueapps\core\exceptions\middleware.py 70 process_exception 17576 20260 
 	 捕获未处理异常,异常具体堆栈->[Traceback (most recent call last):
  File "F:\dxr\Myproject\work\home_application\views.py", line 179, in excel_upload
    with transaction.atomic():
NameError: name 'transaction' is not defined

During handling of the above exception, another exception occurred:

Traceback (most recent call last):
  File "D:\python\lib\site-packages\django\core\handlers\base.py", line 113, in _get_response
    response = wrapped_callback(request, *callback_args, **callback_kwargs)
  File "F:\dxr\Myproject\work\home_application\views.py", line 192, in excel_upload
    logger.error('解析excel文件或者数据插入错误')
NameError: name 'logger' is not defined
], 请求URL->[/excel_upload/], 请求方法->[POST] 请求参数->[{"csrfmiddlewaretoken": "B8RUwkqkCdZHbXDACs5prufMN3VaH9i17uga20OIu4cDFYgIH5n0rikH1obE5QWu"}] 

ERROR [2020-08-14 16:37:07] F:\dxr\Myproject\work\home_application\views.py 180 excel_upload 18924 780 
 	 解析excel文件或者数据插入错误 

ERROR [2020-08-14 16:38:04] F:\dxr\Myproject\work\home_application\views.py 180 excel_upload 18924 7692 
 	 解析excel文件或者数据插入错误 

ERROR [2020-08-14 16:38:14] F:\dxr\Myproject\work\home_application\views.py 180 excel_upload 18924 18352 
 	 解析excel文件或者数据插入错误 

ERROR [2020-08-14 16:45:34] F:\dxr\Myproject\work\home_application\views.py 180 excel_upload 19800 780 
 	 解析excel文件或者数据插入错误 

ERROR [2020-08-17 14:11:03] F:\dxr\Myproject\work\blueapps\core\exceptions\middleware.py 70 process_exception 17724 18020 
 	 捕获未处理异常,异常具体堆栈->[Traceback (most recent call last):
  File "D:\python\lib\site-packages\django\core\handlers\base.py", line 113, in _get_response
    response = wrapped_callback(request, *callback_args, **callback_kwargs)
  File "F:\dxr\Myproject\work\home_application\views.py", line 105, in search
    elif sort and theme is none:
NameError: name 'none' is not defined
], 请求URL->[/search/], 请求方法->[POST] 请求参数->[{"sort": "\u9009\u62e9\u98792", "theme": "", "content": ""}] 

ERROR [2020-08-17 14:12:06] F:\dxr\Myproject\work\blueapps\core\exceptions\middleware.py 70 process_exception 11560 1052 
 	 捕获未处理异常,异常具体堆栈->[Traceback (most recent call last):
  File "D:\python\lib\site-packages\django\core\handlers\base.py", line 113, in _get_response
    response = wrapped_callback(request, *callback_args, **callback_kwargs)
  File "F:\dxr\Myproject\work\home_application\views.py", line 111, in search
    return render_json(result)
  File "F:\dxr\Myproject\work\home_application\views.py", line 50, in render_json
    return HttpResponse(json.dumps(res_dict), content_type='application/json')
  File "D:\python\lib\json\__init__.py", line 231, in dumps
    return _default_encoder.encode(obj)
  File "D:\python\lib\json\encoder.py", line 199, in encode
    chunks = self.iterencode(o, _one_shot=True)
  File "D:\python\lib\json\encoder.py", line 257, in iterencode
    return _iterencode(o, 0)
  File "D:\python\lib\json\encoder.py", line 179, in default
    raise TypeError(f'Object of type {o.__class__.__name__} '
TypeError: Object of type QuerySet is not JSON serializable
], 请求URL->[/search/], 请求方法->[POST] 请求参数->[{"sort": "\u9009\u62e9\u98792", "theme": "", "content": ""}] 

ERROR [2020-08-17 14:13:07] F:\dxr\Myproject\work\blueapps\core\exceptions\middleware.py 70 process_exception 3860 5728 
 	 捕获未处理异常,异常具体堆栈->[Traceback (most recent call last):
  File "D:\python\lib\site-packages\django\core\handlers\base.py", line 113, in _get_response
    response = wrapped_callback(request, *callback_args, **callback_kwargs)
  File "F:\dxr\Myproject\work\home_application\views.py", line 111, in search
    return render_json(result)
  File "F:\dxr\Myproject\work\home_application\views.py", line 50, in render_json
    return HttpResponse(json.dumps(res_dict), content_type='application/json')
  File "D:\python\lib\json\__init__.py", line 231, in dumps
    return _default_encoder.encode(obj)
  File "D:\python\lib\json\encoder.py", line 199, in encode
    chunks = self.iterencode(o, _one_shot=True)
  File "D:\python\lib\json\encoder.py", line 257, in iterencode
    return _iterencode(o, 0)
  File "D:\python\lib\json\encoder.py", line 179, in default
    raise TypeError(f'Object of type {o.__class__.__name__} '
TypeError: Object of type QuerySet is not JSON serializable
], 请求URL->[/search/], 请求方法->[POST] 请求参数->[{"sort": "\u9009\u62e9\u98792", "theme": "", "content": ""}] 

ERROR [2020-08-17 14:13:29] F:\dxr\Myproject\work\blueapps\core\exceptions\middleware.py 70 process_exception 3860 5728 
 	 捕获未处理异常,异常具体堆栈->[Traceback (most recent call last):
  File "D:\python\lib\site-packages\django\core\handlers\base.py", line 113, in _get_response
    response = wrapped_callback(request, *callback_args, **callback_kwargs)
  File "F:\dxr\Myproject\work\home_application\views.py", line 111, in search
    return render_json(result)
  File "F:\dxr\Myproject\work\home_application\views.py", line 50, in render_json
    return HttpResponse(json.dumps(res_dict), content_type='application/json')
  File "D:\python\lib\json\__init__.py", line 231, in dumps
    return _default_encoder.encode(obj)
  File "D:\python\lib\json\encoder.py", line 199, in encode
    chunks = self.iterencode(o, _one_shot=True)
  File "D:\python\lib\json\encoder.py", line 257, in iterencode
    return _iterencode(o, 0)
  File "D:\python\lib\json\encoder.py", line 179, in default
    raise TypeError(f'Object of type {o.__class__.__name__} '
TypeError: Object of type QuerySet is not JSON serializable
], 请求URL->[/search/], 请求方法->[POST] 请求参数->[{"sort": "\u9009\u62e9\u98791", "theme": "", "content": ""}] 

ERROR [2020-08-17 14:15:49] F:\dxr\Myproject\work\blueapps\core\exceptions\middleware.py 70 process_exception 17196 7620 
 	 捕获未处理异常,异常具体堆栈->[Traceback (most recent call last):
  File "D:\python\lib\site-packages\django\core\handlers\base.py", line 113, in _get_response
    response = wrapped_callback(request, *callback_args, **callback_kwargs)
  File "F:\dxr\Myproject\work\home_application\views.py", line 108, in search
    result = workRecord.objects.filter(data)
  File "D:\python\lib\site-packages\django\db\models\manager.py", line 82, in manager_method
    return getattr(self.get_queryset(), name)(*args, **kwargs)
  File "D:\python\lib\site-packages\django\db\models\query.py", line 892, in filter
    return self._filter_or_exclude(False, *args, **kwargs)
  File "D:\python\lib\site-packages\django\db\models\query.py", line 910, in _filter_or_exclude
    clone.query.add_q(Q(*args, **kwargs))
  File "D:\python\lib\site-packages\django\db\models\sql\query.py", line 1290, in add_q
    clause, _ = self._add_q(q_object, self.used_aliases)
  File "D:\python\lib\site-packages\django\db\models\sql\query.py", line 1318, in _add_q
    split_subq=split_subq, simple_col=simple_col,
  File "D:\python\lib\site-packages\django\db\models\sql\query.py", line 1186, in build_filter
    raise FieldError("Cannot parse keyword query as dict")
django.core.exceptions.FieldError: Cannot parse keyword query as dict
], 请求URL->[/search/], 请求方法->[POST] 请求参数->[{"sort": "\u9009\u62e9\u98791", "theme": "", "content": ""}] 

ERROR [2020-08-17 14:20:05] F:\dxr\Myproject\work\blueapps\core\exceptions\middleware.py 70 process_exception 6672 17168 
 	 捕获未处理异常,异常具体堆栈->[Traceback (most recent call last):
  File "D:\python\lib\site-packages\django\core\handlers\base.py", line 113, in _get_response
    response = wrapped_callback(request, *callback_args, **callback_kwargs)
  File "F:\dxr\Myproject\work\home_application\views.py", line 105, in search
    return render_json(result)
  File "F:\dxr\Myproject\work\home_application\views.py", line 50, in render_json
    return HttpResponse(json.dumps(res_dict), content_type='application/json')
  File "D:\python\lib\json\__init__.py", line 231, in dumps
    return _default_encoder.encode(obj)
  File "D:\python\lib\json\encoder.py", line 199, in encode
    chunks = self.iterencode(o, _one_shot=True)
  File "D:\python\lib\json\encoder.py", line 257, in iterencode
    return _iterencode(o, 0)
  File "D:\python\lib\json\encoder.py", line 179, in default
    raise TypeError(f'Object of type {o.__class__.__name__} '
TypeError: Object of type QuerySet is not JSON serializable
], 请求URL->[/search/], 请求方法->[POST] 请求参数->[{"sort": "\u9009\u62e9\u98793", "theme": "", "content": ""}] 

ERROR [2020-08-17 14:54:37] F:\dxr\Myproject\work\blueapps\core\exceptions\middleware.py 70 process_exception 8996 8936 
 	 捕获未处理异常,异常具体堆栈->[Traceback (most recent call last):
  File "D:\python\lib\site-packages\django\core\handlers\base.py", line 113, in _get_response
    response = wrapped_callback(request, *callback_args, **callback_kwargs)
  File "F:\dxr\Myproject\work\home_application\views.py", line 106, in search
    return render_json({'results': true, 'message': 'success', 'data': mydata})
NameError: name 'true' is not defined
], 请求URL->[/search/], 请求方法->[POST] 请求参数->[{"sort": "\u9009\u62e9\u98794"}] 

ERROR [2020-08-17 15:04:23] F:\dxr\Myproject\work\blueapps\core\exceptions\middleware.py 70 process_exception 17720 16764 
 	 捕获未处理异常,异常具体堆栈->[Traceback (most recent call last):
  File "D:\python\lib\site-packages\django\db\models\sql\query.py", line 1768, in add_fields
    join_info = self.setup_joins(name.split(LOOKUP_SEP), opts, alias, allow_many=allow_m2m)
  File "D:\python\lib\site-packages\django\db\models\sql\query.py", line 1504, in setup_joins
    names[:pivot], opts, allow_many, fail_on_missing=True,
  File "D:\python\lib\site-packages\django\db\models\sql\query.py", line 1420, in names_to_path
    "Choices are: %s" % (name, ", ".join(available)))
django.core.exceptions.FieldError: Cannot resolve keyword 'index' into field. Choices are: content, id, operator, record_time, sort, theme

During handling of the above exception, another exception occurred:

Traceback (most recent call last):
  File "D:\python\lib\site-packages\django\core\handlers\base.py", line 113, in _get_response
    response = wrapped_callback(request, *callback_args, **callback_kwargs)
  File "F:\dxr\Myproject\work\home_application\views.py", line 104, in search
    result = workRecord.objects.filter(sort = sort).values('index','sort','theme','content')
  File "D:\python\lib\site-packages\django\db\models\query.py", line 798, in values
    clone = self._values(*fields, **expressions)
  File "D:\python\lib\site-packages\django\db\models\query.py", line 793, in _values
    clone.query.set_values(fields)
  File "D:\python\lib\site-packages\django\db\models\sql\query.py", line 2020, in set_values
    self.add_fields(field_names, True)
  File "D:\python\lib\site-packages\django\db\models\sql\query.py", line 1791, in add_fields
    "Choices are: %s" % (name, ", ".join(names)))
django.core.exceptions.FieldError: Cannot resolve keyword 'index' into field. Choices are: content, id, operator, record_time, sort, theme
], 请求URL->[/search/], 请求方法->[POST] 请求参数->[{"sort": "\u9009\u62e9\u98794"}] 

ERROR [2020-08-17 15:11:05] F:\dxr\Myproject\work\home_application\views.py 213 excel_upload 5176 16264 
 	 解析excel文件或者数据插入错误 

ERROR [2020-08-17 16:36:14] F:\dxr\Myproject\work\blueapps\core\exceptions\middleware.py 70 process_exception 11436 10948 
 	 捕获未处理异常,异常具体堆栈->[Traceback (most recent call last):
  File "D:\python\lib\site-packages\django\core\handlers\base.py", line 113, in _get_response
    response = wrapped_callback(request, *callback_args, **callback_kwargs)
  File "F:\dxr\Myproject\work\home_application\views.py", line 177, in export_excel
    sheet.write(data_row,0,i.id)
AttributeError: 'dict' object has no attribute 'id'
], 请求URL->[/export_excel/], 请求方法->[POST] 请求参数->[{"sort": "\u9009\u62e9\u98791", "theme": ""}] 

ERROR [2020-08-17 16:38:43] F:\dxr\Myproject\work\blueapps\core\exceptions\middleware.py 70 process_exception 16088 15632 
 	 捕获未处理异常,异常具体堆栈->[Traceback (most recent call last):
  File "D:\python\lib\site-packages\django\core\handlers\base.py", line 113, in _get_response
    response = wrapped_callback(request, *callback_args, **callback_kwargs)
  File "F:\dxr\Myproject\work\home_application\views.py", line 175, in export_excel
    console.log(result)
NameError: name 'console' is not defined
], 请求URL->[/export_excel/], 请求方法->[POST] 请求参数->[{"sort": "\u9009\u62e9\u98791", "theme": ""}] 

ERROR [2020-08-17 16:39:13] F:\dxr\Myproject\work\blueapps\core\exceptions\middleware.py 70 process_exception 17328 2764 
 	 捕获未处理异常,异常具体堆栈->[Traceback (most recent call last):
  File "D:\python\lib\site-packages\django\core\handlers\base.py", line 113, in _get_response
    response = wrapped_callback(request, *callback_args, **callback_kwargs)
  File "F:\dxr\Myproject\work\home_application\views.py", line 178, in export_excel
    sheet.write(data_row,0,i.id)
AttributeError: 'dict' object has no attribute 'id'
], 请求URL->[/export_excel/], 请求方法->[POST] 请求参数->[{"sort": "\u9009\u62e9\u98791", "theme": ""}] 

ERROR [2020-08-17 16:40:35] F:\dxr\Myproject\work\blueapps\core\exceptions\middleware.py 70 process_exception 2468 15052 
 	 捕获未处理异常,异常具体堆栈->[Traceback (most recent call last):
  File "D:\python\lib\site-packages\django\core\handlers\base.py", line 113, in _get_response
    response = wrapped_callback(request, *callback_args, **callback_kwargs)
  File "F:\dxr\Myproject\work\home_application\views.py", line 178, in export_excel
    sheet.write(data_row,0,i.id)
AttributeError: 'dict' object has no attribute 'id'
], 请求URL->[/export_excel/], 请求方法->[POST] 请求参数->[{"sort": "\u9009\u62e9\u98791", "theme": ""}] 

ERROR [2020-08-17 16:41:02] F:\dxr\Myproject\work\blueapps\core\exceptions\middleware.py 70 process_exception 11752 14656 
 	 捕获未处理异常,异常具体堆栈->[Traceback (most recent call last):
  File "D:\python\lib\site-packages\django\core\handlers\base.py", line 113, in _get_response
    response = wrapped_callback(request, *callback_args, **callback_kwargs)
  File "F:\dxr\Myproject\work\home_application\views.py", line 177, in export_excel
    print(i.id)
AttributeError: 'dict' object has no attribute 'id'
], 请求URL->[/export_excel/], 请求方法->[POST] 请求参数->[{"sort": "\u9009\u62e9\u98791", "theme": ""}] 

ERROR [2020-08-18 11:33:04] F:\dxr\Myproject\work\home_application\views.py 248 excel_upload 7584 13348 
 	 解析excel文件或者数据插入错误 

ERROR [2020-08-18 11:38:27] F:\dxr\Myproject\work\home_application\views.py 248 excel_upload 11344 6256 
 	 解析excel文件或者数据插入错误 

ERROR [2020-08-18 11:42:56] F:\dxr\Myproject\work\home_application\views.py 248 excel_upload 11344 15236 
 	 解析excel文件或者数据插入错误 

ERROR [2020-08-18 11:46:49] F:\dxr\Myproject\work\home_application\views.py 248 excel_upload 11344 13688 
 	 解析excel文件或者数据插入错误 

ERROR [2020-08-18 11:54:05] F:\dxr\Myproject\work\home_application\views.py 248 excel_upload 11344 14732 
 	 解析excel文件或者数据插入错误 

ERROR [2020-08-18 11:55:34] F:\dxr\Myproject\work\home_application\views.py 248 excel_upload 11344 2964 
 	 解析excel文件或者数据插入错误 

ERROR [2020-08-18 11:56:52] F:\dxr\Myproject\work\home_application\views.py 249 excel_upload 15916 424 
 	 解析excel文件或者数据插入错误 

ERROR [2020-08-18 11:57:50] F:\dxr\Myproject\work\home_application\views.py 249 excel_upload 14040 16508 
 	 解析excel文件或者数据插入错误 

ERROR [2020-08-18 11:58:46] F:\dxr\Myproject\work\home_application\views.py 247 excel_upload 14640 16160 
 	 解析excel文件或者数据插入错误 

ERROR [2020-08-18 11:59:50] F:\dxr\Myproject\work\home_application\views.py 247 excel_upload 8024 10428 
 	 解析excel文件或者数据插入错误 

ERROR [2020-08-18 12:37:45] F:\dxr\Myproject\work\home_application\views.py 246 excel_upload 17652 4336 
 	 解析excel文件或者数据插入错误 

